2023-04-17 15:43:19.145 | DEBUG    | __main__:serve:17 - 启动服务0:50051
2023-04-17 15:43:30.897 | ERROR    | grpc._server:_call_behavior:435 - An error has been caught in function '_call_behavior', process 'MainProcess' (6684), thread 'ThreadPoolExecutor-0_0' (7408):
Traceback (most recent call last):

  File "C:\Users\ND01\anaconda3\envs\mxshop_srvs\lib\threading.py", line 890, in _bootstrap
    self._bootstrap_inner()
    │    └ <function Thread._bootstrap_inner at 0x000002204ABCDD30>
    └ <Thread(ThreadPoolExecutor-0_0, started daemon 7408)>

  File "C:\Users\ND01\anaconda3\envs\mxshop_srvs\lib\threading.py", line 932, in _bootstrap_inner
    self.run()
    │    └ <function Thread.run at 0x000002204ABCDA60>
    └ <Thread(ThreadPoolExecutor-0_0, started daemon 7408)>

  File "C:\Users\ND01\anaconda3\envs\mxshop_srvs\lib\threading.py", line 870, in run
    self._target(*self._args, **self._kwargs)
    │    │        │    │        │    └ {}
    │    │        │    │        └ <Thread(ThreadPoolExecutor-0_0, started daemon 7408)>
    │    │        │    └ (<weakref at 0x000002204BF92900; to 'ThreadPoolExecutor' at 0x000002204BE56AF0>, <_queue.SimpleQueue object at 0x000002204BE4...
    │    │        └ <Thread(ThreadPoolExecutor-0_0, started daemon 7408)>
    │    └ <function _worker at 0x000002204BE5D940>
    └ <Thread(ThreadPoolExecutor-0_0, started daemon 7408)>

  File "C:\Users\ND01\anaconda3\envs\mxshop_srvs\lib\concurrent\futures\thread.py", line 80, in _worker
    work_item.run()
    │         └ <function _WorkItem.run at 0x000002204BE5DA60>
    └ <concurrent.futures.thread._WorkItem object at 0x000002204BF90DC0>

  File "C:\Users\ND01\anaconda3\envs\mxshop_srvs\lib\concurrent\futures\thread.py", line 57, in run
    result = self.fn(*self.args, **self.kwargs)
             │    │   │    │       │    └ {}
             │    │   │    │       └ <concurrent.futures.thread._WorkItem object at 0x000002204BF90DC0>
             │    │   │    └ [<grpc._cython.cygrpc.RequestCallEvent object at 0x000002204BF92310>, <grpc._server._RPCState object at 0x000002204BF90B80>, ...
             │    │   └ <concurrent.futures.thread._WorkItem object at 0x000002204BF90DC0>
             │    └ <function _unary_response_in_pool at 0x000002204BE89280>
             └ <concurrent.futures.thread._WorkItem object at 0x000002204BF90DC0>

  File "C:\Users\ND01\anaconda3\envs\mxshop_srvs\lib\site-packages\grpc\_server.py", line 552, in _unary_response_in_pool
    response, proceed = _call_behavior(rpc_event, state, behavior,
                        │              │          │      └ <bound method UserServicer.GetUserList of <user_srv.handler.user.UserServicer object at 0x000002204BE63D30>>
                        │              │          └ <grpc._server._RPCState object at 0x000002204BF90B80>
                        │              └ <grpc._cython.cygrpc.RequestCallEvent object at 0x000002204BF92310>
                        └ <function _call_behavior at 0x000002204BE8BE50>

> File "C:\Users\ND01\anaconda3\envs\mxshop_srvs\lib\site-packages\grpc\_server.py", line 435, in _call_behavior
    response_or_iterator = behavior(argument, context)
                           │        │         └ <grpc._server._Context object at 0x000002204BF99220>
                           │        └ Page: 2
                           │          PageSize: 2
                           │          
                           └ <bound method UserServicer.GetUserList of <user_srv.handler.user.UserServicer object at 0x000002204BE63D30>>

  File "F:\goProject\go-python-project\mxshop_srvs\user_srv\handler\user.py", line 25, in GetUserList
    a[1] = 10
    └ []

IndexError: list assignment index out of range
