2023-04-17 15:48:21.478 | DEBUG    | __main__:serve:17 - 启动服务0:50051
2023-04-17 15:48:25.795 | ERROR    | grpc._server:_call_behavior:435 - An error has been caught in function '_call_behavior', process 'MainProcess' (11556), thread 'ThreadPoolExecutor-0_0' (8488):
Traceback (most recent call last):

  File "C:\Users\ND01\anaconda3\envs\mxshop_srvs\lib\threading.py", line 890, in _bootstrap
    self._bootstrap_inner()
    │    └ <function Thread._bootstrap_inner at 0x00000178A2F1DD30>
    └ <Thread(ThreadPoolExecutor-0_0, started daemon 8488)>

  File "C:\Users\ND01\anaconda3\envs\mxshop_srvs\lib\threading.py", line 932, in _bootstrap_inner
    self.run()
    │    └ <function Thread.run at 0x00000178A2F1DA60>
    └ <Thread(ThreadPoolExecutor-0_0, started daemon 8488)>

  File "C:\Users\ND01\anaconda3\envs\mxshop_srvs\lib\threading.py", line 870, in run
    self._target(*self._args, **self._kwargs)
    │    │        │    │        │    └ {}
    │    │        │    │        └ <Thread(ThreadPoolExecutor-0_0, started daemon 8488)>
    │    │        │    └ (<weakref at 0x00000178A42E55E0; to 'ThreadPoolExecutor' at 0x00000178A41A6AF0>, <_queue.SimpleQueue object at 0x00000178A419...
    │    │        └ <Thread(ThreadPoolExecutor-0_0, started daemon 8488)>
    │    └ <function _worker at 0x00000178A41AC940>
    └ <Thread(ThreadPoolExecutor-0_0, started daemon 8488)>

  File "C:\Users\ND01\anaconda3\envs\mxshop_srvs\lib\concurrent\futures\thread.py", line 80, in _worker
    work_item.run()
    │         └ <function _WorkItem.run at 0x00000178A41ACA60>
    └ <concurrent.futures.thread._WorkItem object at 0x00000178A42E0DC0>

  File "C:\Users\ND01\anaconda3\envs\mxshop_srvs\lib\concurrent\futures\thread.py", line 57, in run
    result = self.fn(*self.args, **self.kwargs)
             │    │   │    │       │    └ {}
             │    │   │    │       └ <concurrent.futures.thread._WorkItem object at 0x00000178A42E0DC0>
             │    │   │    └ [<grpc._cython.cygrpc.RequestCallEvent object at 0x00000178A42E51D0>, <grpc._server._RPCState object at 0x00000178A42E0B80>, ...
             │    │   └ <concurrent.futures.thread._WorkItem object at 0x00000178A42E0DC0>
             │    └ <function _unary_response_in_pool at 0x00000178A41D8280>
             └ <concurrent.futures.thread._WorkItem object at 0x00000178A42E0DC0>

  File "C:\Users\ND01\anaconda3\envs\mxshop_srvs\lib\site-packages\grpc\_server.py", line 552, in _unary_response_in_pool
    response, proceed = _call_behavior(rpc_event, state, behavior,
                        │              │          │      └ <bound method UserServicer.GetUserList of <user_srv.handler.user.UserServicer object at 0x00000178A41B3D30>>
                        │              │          └ <grpc._server._RPCState object at 0x00000178A42E0B80>
                        │              └ <grpc._cython.cygrpc.RequestCallEvent object at 0x00000178A42E51D0>
                        └ <function _call_behavior at 0x00000178A41D9E50>

> File "C:\Users\ND01\anaconda3\envs\mxshop_srvs\lib\site-packages\grpc\_server.py", line 435, in _call_behavior
    response_or_iterator = behavior(argument, context)
                           │        │         └ <grpc._server._Context object at 0x00000178A42E9220>
                           │        └ Page: 2
                           │          PageSize: 2
                           │          
                           └ <bound method UserServicer.GetUserList of <user_srv.handler.user.UserServicer object at 0x00000178A41B3D30>>

  File "F:\goProject\go-python-project\mxshop_srvs\user_srv\handler\user.py", line 25, in GetUserList
    a[1] = 10
    └ []

IndexError: list assignment index out of range
2023-04-17 15:49:14.145 | ERROR    | grpc._server:_call_behavior:435 - An error has been caught in function '_call_behavior', process 'MainProcess' (11556), thread 'ThreadPoolExecutor-0_0' (8488):
Traceback (most recent call last):

  File "C:\Users\ND01\anaconda3\envs\mxshop_srvs\lib\threading.py", line 890, in _bootstrap
    self._bootstrap_inner()
    │    └ <function Thread._bootstrap_inner at 0x00000178A2F1DD30>
    └ <Thread(ThreadPoolExecutor-0_0, started daemon 8488)>

  File "C:\Users\ND01\anaconda3\envs\mxshop_srvs\lib\threading.py", line 932, in _bootstrap_inner
    self.run()
    │    └ <function Thread.run at 0x00000178A2F1DA60>
    └ <Thread(ThreadPoolExecutor-0_0, started daemon 8488)>

  File "C:\Users\ND01\anaconda3\envs\mxshop_srvs\lib\threading.py", line 870, in run
    self._target(*self._args, **self._kwargs)
    │    │        │    │        │    └ {}
    │    │        │    │        └ <Thread(ThreadPoolExecutor-0_0, started daemon 8488)>
    │    │        │    └ (<weakref at 0x00000178A42E55E0; to 'ThreadPoolExecutor' at 0x00000178A41A6AF0>, <_queue.SimpleQueue object at 0x00000178A419...
    │    │        └ <Thread(ThreadPoolExecutor-0_0, started daemon 8488)>
    │    └ <function _worker at 0x00000178A41AC940>
    └ <Thread(ThreadPoolExecutor-0_0, started daemon 8488)>

  File "C:\Users\ND01\anaconda3\envs\mxshop_srvs\lib\concurrent\futures\thread.py", line 80, in _worker
    work_item.run()
    │         └ <function _WorkItem.run at 0x00000178A41ACA60>
    └ <concurrent.futures.thread._WorkItem object at 0x00000178A42FFB20>

  File "C:\Users\ND01\anaconda3\envs\mxshop_srvs\lib\concurrent\futures\thread.py", line 57, in run
    result = self.fn(*self.args, **self.kwargs)
             │    │   │    │       │    └ {}
             │    │   │    │       └ <concurrent.futures.thread._WorkItem object at 0x00000178A42FFB20>
             │    │   │    └ [<grpc._cython.cygrpc.RequestCallEvent object at 0x00000178A417F770>, <grpc._server._RPCState object at 0x00000178A42E9220>, ...
             │    │   └ <concurrent.futures.thread._WorkItem object at 0x00000178A42FFB20>
             │    └ <function _unary_response_in_pool at 0x00000178A41D8280>
             └ <concurrent.futures.thread._WorkItem object at 0x00000178A42FFB20>

  File "C:\Users\ND01\anaconda3\envs\mxshop_srvs\lib\site-packages\grpc\_server.py", line 552, in _unary_response_in_pool
    response, proceed = _call_behavior(rpc_event, state, behavior,
                        │              │          │      └ <bound method UserServicer.GetUserList of <user_srv.handler.user.UserServicer object at 0x00000178A41B3D30>>
                        │              │          └ <grpc._server._RPCState object at 0x00000178A42E9220>
                        │              └ <grpc._cython.cygrpc.RequestCallEvent object at 0x00000178A417F770>
                        └ <function _call_behavior at 0x00000178A41D9E50>

> File "C:\Users\ND01\anaconda3\envs\mxshop_srvs\lib\site-packages\grpc\_server.py", line 435, in _call_behavior
    response_or_iterator = behavior(argument, context)
                           │        │         └ <grpc._server._Context object at 0x00000178A42FFCA0>
                           │        └ Page: 2
                           │          PageSize: 2
                           │          
                           └ <bound method UserServicer.GetUserList of <user_srv.handler.user.UserServicer object at 0x00000178A41B3D30>>

  File "F:\goProject\go-python-project\mxshop_srvs\user_srv\handler\user.py", line 25, in GetUserList
    a[1] = 10
    └ []

IndexError: list assignment index out of range
